<?xml version="1.0"?>

<robot name="robot">

  <material name="blue">
    <color rgba="0 0 1 1"/>
  </material>
  <material name="red">
    <color rgba="1 0 0 1"/>
  </material>
  <material name="green">
  <color rgba="0 1 0 1"/>
</material>
  <material name="white">
  <color rgba="1 1 1 1"/>
</material>
  <material name="black">
  <color rgba="0 0 0 1"/>
</material>
  <material name="yellow">
  <color rgba="1 1 0 1"/>
</material>

<!--
  <link name="world">
  </link>

  <joint name="base_planar_full" type="planar">
    <parent link="world"/>
    <child link="chassis"/>
    <origin xyz="0 0 0" rpy="0 0 0"/>
    <axis xyz="0 0 1"/>
    <limit lower="-3.14159" upper="3.14159" effort="0" velocity="0"/>
</joint>
-->


  <link name="chassis">
    <visual>
      <geometry>
        <box size="0.75 0.75 0.75"/>
      </geometry>
      <material name="black"/>
    </visual>
    <collision>
      <geometry>
        <box size="0.75 0.75 0.75"/>
      </geometry>
    </collision>
    <inertial>
      <mass value="10"/>
      <!--<inertia ixx="0.095" ixy="0.0" ixz="0.0" iyy="0.381" iyz="0.0" izz="0.476"/>-->
        <inertia ixx="0.46875" iyy="0.46875" izz="0.46875" ixy="0" ixz="0" iyz="0"/>
    </inertial>
  </link>

  <link name="left_wheel">
    <visual>
      <geometry>
        <cylinder length="0.1" radius="0.2"/>
      </geometry>
      <material name="black"/>
    </visual>
    <collision>
      <geometry>
        <cylinder length="0.1" radius="0.2"/>
      </geometry>
    </collision>
    <inertial>
      <mass value="1"/>
      <inertia ixx="0.005" ixy="0.0" ixz="0.0" iyy="0.005" iyz="0.0" izz="0.01"/>
    </inertial>
  </link>


<link name="left_wheel_roller1">
  <visual>
    <geometry>
      <cylinder length="0.15" radius="0.05"/>
    </geometry>
    <material name="white"/>
  </visual>
  <collision>
    <geometry>
      <cylinder length="0.15" radius="0.05"/>
    </geometry>
  </collision>
  <inertial>
    <mass value="0.1"/>
    <inertia ixx="0.0001" iyy="0.0001" izz="0.0001"/>
  </inertial>
</link>
<joint name="left_wheel_roller1_joint" type="fixed">
  <parent link="left_wheel"/>
  <child link="left_wheel_roller1"/>
  <origin xyz="0.2 0 0" rpy="1.5707 0 0"/>
</joint>

<link name="left_wheel_roller2">
  <visual>
    <geometry>
      <cylinder length="0.15" radius="0.05"/>
    </geometry>
    <material name="white"/>
  </visual>
  <collision>
    <geometry>
      <cylinder length="0.15" radius="0.05"/>
    </geometry>
  </collision>
  <inertial>
    <mass value="0.1"/>
    <inertia ixx="0.0001" iyy="0.0001" izz="0.0001"/>
  </inertial>
</link>
<joint name="left_wheel_roller2_joint" type="fixed">
  <parent link="left_wheel"/>
  <child link="left_wheel_roller2"/>
  <origin xyz="-0.2 0 0" rpy="1.5707 0 0"/>
</joint>

<link name="left_wheel_roller3">
  <visual>
    <geometry>
      <cylinder length="0.15" radius="0.05"/>
    </geometry>
    <material name="white"/>
  </visual>
  <collision>
    <geometry>
      <cylinder length="0.15" radius="0.05"/>
    </geometry>
  </collision>
  <inertial>
    <mass value="0.1"/>
    <inertia ixx="0.0001" iyy="0.0001" izz="0.0001"/>
  </inertial>
</link>
<joint name="left_wheel_roller3_joint" type="fixed">
  <parent link="left_wheel"/>
  <child link="left_wheel_roller3"/>
  <origin xyz="0.1 0.1732 0" rpy="1.5707 0 1.0472"/>
</joint>

<link name="left_wheel_roller4">
  <visual>
    <geometry>
      <cylinder length="0.15" radius="0.05"/>
    </geometry>
    <material name="white"/>
  </visual>
  <collision>
    <geometry>
      <cylinder length="0.15" radius="0.05"/>
    </geometry>
  </collision>
  <inertial>
    <mass value="0.1"/>
    <inertia ixx="0.0001" iyy="0.0001" izz="0.0001"/>
  </inertial>
</link>
<joint name="left_wheel_roller4_joint" type="fixed">
  <parent link="left_wheel"/>
  <child link="left_wheel_roller4"/>
  <origin xyz="-0.1 -0.1732 0" rpy="1.5707 0 1.0472"/>
</joint>

<link name="left_wheel_roller5">
  <visual>
    <geometry>
      <cylinder length="0.15" radius="0.05"/>
    </geometry>
    <material name="white"/>
  </visual>
  <collision>
    <geometry>
      <cylinder length="0.15" radius="0.05"/>
    </geometry>
  </collision>
  <inertial>
    <mass value="0.1"/>
    <inertia ixx="0.0001" iyy="0.0001" izz="0.0001"/>
  </inertial>
</link>
<joint name="left_wheel_roller5_joint" type="fixed">
  <parent link="left_wheel"/>
  <child link="left_wheel_roller5"/>
  <origin xyz="0.1 -0.1732 0" rpy="1.5707 0 2.0944"/>
</joint>

<link name="left_wheel_roller6">
  <visual>
    <geometry>
      <cylinder length="0.15" radius="0.05"/>
    </geometry>
    <material name="white"/>
  </visual>
  <collision>
    <geometry>
      <cylinder length="0.15" radius="0.05"/>
    </geometry>
  </collision>
  <inertial>
    <mass value="0.1"/>
    <inertia ixx="0.0001" iyy="0.0001" izz="0.0001"/>
  </inertial>
</link>
<joint name="left_wheel_roller6_joint" type="fixed">
  <parent link="left_wheel"/>
  <child link="left_wheel_roller6"/>
  <origin xyz="-0.1 0.1732 0" rpy="1.5707 0 2.0944"/>
</joint>

  <joint name="left_wheel_joint" type="continuous">
    <parent link="chassis"/>
    <child link="left_wheel"/>
    <origin rpy="-1.5707 0 0" xyz="0 0.4 -0.3"/>
    <axis xyz="0 0 1"/>
  </joint>



  <link name="right_wheel">
    <visual>
      <geometry>
        <cylinder length="0.1" radius="0.2"/>
      </geometry>
      <material name="black"/>
    </visual>
    <collision>
      <geometry>
        <cylinder length="0.1" radius="0.2"/>
      </geometry>
    </collision>
    <inertial>
      <mass value="1"/>
      <inertia ixx="0.005" ixy="0.0" ixz="0.0" iyy="0.005" iyz="0.0" izz="0.01"/>
    </inertial>
  </link>

  <joint name="right_wheel_joint" type="continuous">
    <parent link="chassis"/>
    <child link="right_wheel"/>
    <origin rpy="-1.5707 0 0" xyz="0 -0.4 -0.3"/>
    <axis xyz="0 0 1"/>
  </joint>

<link name="right_wheel_roller1">
  <visual>
    <geometry>
      <cylinder length="0.15" radius="0.05"/>
    </geometry>
    <material name="white"/>
  </visual>
  <collision>
    <geometry>
      <cylinder length="0.15" radius="0.05"/>
    </geometry>
  </collision>
  <inertial>
    <mass value="0.1"/>
    <inertia ixx="0.0001" iyy="0.0001" izz="0.0001"/>
  </inertial>
</link>
<joint name="right_wheel_roller1_joint" type="fixed">
  <parent link="right_wheel"/>
  <child link="right_wheel_roller1"/>
  <origin xyz="0.2 0 0" rpy="1.5707 0 0"/>
</joint>

<link name="right_wheel_roller2">
  <visual>
    <geometry>
      <cylinder length="0.15" radius="0.05"/>
    </geometry>
    <material name="white"/>
  </visual>
  <collision>
    <geometry>
      <cylinder length="0.15" radius="0.05"/>
    </geometry>
  </collision>
  <inertial>
    <mass value="0.1"/>
    <inertia ixx="0.0001" iyy="0.0001" izz="0.0001"/>
  </inertial>
</link>
<joint name="right_wheel_roller2_joint" type="fixed">
  <parent link="right_wheel"/>
  <child link="right_wheel_roller2"/>
  <origin xyz="-0.2 0 0" rpy="1.5707 0 0"/>
</joint>

<link name="right_wheel_roller3">
  <visual>
    <geometry>
      <cylinder length="0.15" radius="0.05"/>
    </geometry>
    <material name="white"/>
  </visual>
  <collision>
    <geometry>
      <cylinder length="0.15" radius="0.05"/>
    </geometry>
  </collision>
  <inertial>
    <mass value="0.1"/>
    <inertia ixx="0.0001" iyy="0.0001" izz="0.0001"/>
  </inertial>
</link>
<joint name="right_wheel_roller3_joint" type="fixed">
  <parent link="right_wheel"/>
  <child link="right_wheel_roller3"/>
  <origin xyz="0.1 0.1732 0" rpy="1.5707 0 1.0472"/>
</joint>

<link name="right_wheel_roller4">
  <visual>
    <geometry>
      <cylinder length="0.15" radius="0.05"/>
    </geometry>
    <material name="white"/>
  </visual>
  <collision>
    <geometry>
      <cylinder length="0.15" radius="0.05"/>
    </geometry>
  </collision>
  <inertial>
    <mass value="0.1"/>
    <inertia ixx="0.0001" iyy="0.0001" izz="0.0001"/>
  </inertial>
</link>
<joint name="right_wheel_roller4_joint" type="fixed">
  <parent link="right_wheel"/>
  <child link="right_wheel_roller4"/>
  <origin xyz="-0.1 -0.1732 0" rpy="1.5707 0 1.0472"/>
</joint>

<link name="right_wheel_roller5">
  <visual>
    <geometry>
      <cylinder length="0.15" radius="0.05"/>
    </geometry>
    <material name="white"/>
  </visual>
  <collision>
    <geometry>
      <cylinder length="0.15" radius="0.05"/>
    </geometry>
  </collision>
  <inertial>
    <mass value="0.1"/>
    <inertia ixx="0.0001" iyy="0.0001" izz="0.0001"/>
  </inertial>
</link>
<joint name="right_wheel_roller5_joint" type="fixed">
  <parent link="right_wheel"/>
  <child link="right_wheel_roller5"/>
  <origin xyz="0.1 -0.1732 0" rpy="1.5707 0 2.0944"/>
</joint>

<link name="right_wheel_roller6">
  <visual>
    <geometry>
      <cylinder length="0.15" radius="0.05"/>
    </geometry>
    <material name="white"/>
  </visual>
  <collision>
    <geometry>
      <cylinder length="0.15" radius="0.05"/>
    </geometry>
  </collision>
  <inertial>
    <mass value="0.1"/>
    <inertia ixx="0.0001" iyy="0.0001" izz="0.0001"/>
  </inertial>
</link>
<joint name="right_wheel_roller6_joint" type="fixed">
  <parent link="right_wheel"/>
  <child link="right_wheel_roller6"/>
  <origin xyz="-0.1 0.1732 0" rpy="1.5707 0 2.0944"/>
</joint>



  <link name="front_wheel">
    <visual>
      <geometry>
        <cylinder length="0.1" radius="0.2"/>
      </geometry>
      <material name="black"/>
    </visual>
    <collision>
      <geometry>
        <cylinder length="0.1" radius="0.2"/>
      </geometry>
    </collision>
    <inertial>
      <mass value="1"/>
      <inertia ixx="0.005" ixy="0.0" ixz="0.0" iyy="0.005" iyz="0.0" izz="0.01"/>
    </inertial>
  </link>

  <joint name="front_wheel_joint" type="continuous">
    <parent link="chassis"/>
    <child link="front_wheel"/>
    <origin rpy="-1.5707 0 1.5707" xyz="0.4 0 -0.3"/>
    <axis xyz="0 0 1"/>
  </joint>


  <link name="front_wheel_roller1">
  <visual>
    <geometry>
      <cylinder length="0.15" radius="0.05"/>
    </geometry>
    <material name="white"/>
  </visual>
  <collision>
    <geometry>
      <cylinder length="0.15" radius="0.05"/>
    </geometry>
  </collision>
  <inertial>
    <mass value="0.1"/>
    <inertia ixx="0.0001" iyy="0.0001" izz="0.0001"/>
  </inertial>
</link>
<joint name="front_wheel_roller1_joint" type="fixed">
  <parent link="front_wheel"/>
  <child link="front_wheel_roller1"/>
  <origin xyz="0.2 0 0" rpy="1.5707 0 0"/>
</joint>

<link name="front_wheel_roller2">
  <visual>
    <geometry>
      <cylinder length="0.15" radius="0.05"/>
    </geometry>
    <material name="white"/>
  </visual>
  <collision>
    <geometry>
      <cylinder length="0.15" radius="0.05"/>
    </geometry>
  </collision>
  <inertial>
    <mass value="0.1"/>
    <inertia ixx="0.0001" iyy="0.0001" izz="0.0001"/>
  </inertial>
</link>
<joint name="front_wheel_roller2_joint" type="fixed">
  <parent link="front_wheel"/>
  <child link="front_wheel_roller2"/>
  <origin xyz="-0.2 0 0" rpy="1.5707 0 0"/>
</joint>

<link name="front_wheel_roller3">
  <visual>
    <geometry>
      <cylinder length="0.15" radius="0.05"/>
    </geometry>
    <material name="white"/>
  </visual>
  <collision>
    <geometry>
      <cylinder length="0.15" radius="0.05"/>
    </geometry>
  </collision>
  <inertial>
    <mass value="0.1"/>
    <inertia ixx="0.0001" iyy="0.0001" izz="0.0001"/>
  </inertial>
</link>
<joint name="front_wheel_roller3_joint" type="fixed">
  <parent link="front_wheel"/>
  <child link="front_wheel_roller3"/>
  <origin xyz="0.1 0.1732 0" rpy="1.5707 0 1.0472"/>
</joint>

<link name="front_wheel_roller4">
  <visual>
    <geometry>
      <cylinder length="0.15" radius="0.05"/>
    </geometry>
    <material name="white"/>
  </visual>
  <collision>
    <geometry>
      <cylinder length="0.15" radius="0.05"/>
    </geometry>
  </collision>
  <inertial>
    <mass value="0.1"/>
    <inertia ixx="0.0001" iyy="0.0001" izz="0.0001"/>
  </inertial>
</link>
<joint name="front_wheel_roller4_joint" type="fixed">
  <parent link="front_wheel"/>
  <child link="front_wheel_roller4"/>
  <origin xyz="-0.1 -0.1732 0" rpy="1.5707 0 1.0472"/>
</joint>

<link name="front_wheel_roller5">
  <visual>
    <geometry>
      <cylinder length="0.15" radius="0.05"/>
    </geometry>
    <material name="white"/>
  </visual>
  <collision>
    <geometry>
      <cylinder length="0.15" radius="0.05"/>
    </geometry>
  </collision>
  <inertial>
    <mass value="0.1"/>
    <inertia ixx="0.0001" iyy="0.0001" izz="0.0001"/>
  </inertial>
</link>
<joint name="front_wheel_roller5_joint" type="fixed">
  <parent link="front_wheel"/>
  <child link="front_wheel_roller5"/>
  <origin xyz="0.1 -0.1732 0" rpy="1.5707 0 2.0944"/>
</joint>

<link name="front_wheel_roller6">
  <visual>
    <geometry>
      <cylinder length="0.15" radius="0.05"/>
    </geometry>
    <material name="white"/>
  </visual>
  <collision>
    <geometry>
      <cylinder length="0.15" radius="0.05"/>
    </geometry>
  </collision>
  <inertial>
    <mass value="0.1"/>
    <inertia ixx="0.0001" iyy="0.0001" izz="0.0001"/>
  </inertial>
</link>
<joint name="front_wheel_roller6_joint" type="fixed">
  <parent link="front_wheel"/>
  <child link="front_wheel_roller6"/>
  <origin xyz="-0.1 0.1732 0" rpy="1.5707 0 2.0944"/>
</joint>




  <link name="back_wheel">
    <visual>
      <geometry>
        <cylinder length="0.1" radius="0.2"/>
      </geometry>
      <material name="black"/>
    </visual>
    <collision>
      <geometry>
        <cylinder length="0.1" radius="0.2"/>
      </geometry>
    </collision>
    <inertial>
      <mass value="1"/>
      <inertia ixx="0.005" ixy="0.0" ixz="0.0" iyy="0.005" iyz="0.0" izz="0.01"/>
    </inertial>
  </link>

  <joint name="back_wheel_joint" type="continuous">
    <parent link="chassis"/>
    <child link="back_wheel"/>
    <origin rpy="-1.5707 0 1.5707" xyz="-0.4 0 -0.3"/>
    <axis xyz="0 0 1"/>
  </joint>

  <link name="back_wheel_roller1">
  <visual>
    <geometry>
      <cylinder length="0.15" radius="0.05"/>
    </geometry>
    <material name="white"/>
  </visual>
  <collision>
    <geometry>
      <cylinder length="0.15" radius="0.05"/>
    </geometry>
  </collision>
  <inertial>
    <mass value="0.1"/>
    <inertia ixx="0.0001" iyy="0.0001" izz="0.0001"/>
  </inertial>
</link>
<joint name="back_wheel_roller1_joint" type="fixed">
  <parent link="back_wheel"/>
  <child link="back_wheel_roller1"/>
  <origin xyz="0.2 0 0" rpy="1.5707 0 0"/>
</joint>

<link name="back_wheel_roller2">
  <visual>
    <geometry>
      <cylinder length="0.15" radius="0.05"/>
    </geometry>
    <material name="white"/>
  </visual>
  <collision>
    <geometry>
      <cylinder length="0.15" radius="0.05"/>
    </geometry>
  </collision>
  <inertial>
    <mass value="0.1"/>
    <inertia ixx="0.0001" iyy="0.0001" izz="0.0001"/>
  </inertial>
</link>
<joint name="back_wheel_roller2_joint" type="fixed">
  <parent link="back_wheel"/>
  <child link="back_wheel_roller2"/>
  <origin xyz="-0.2 0 0" rpy="1.5707 0 0"/>
</joint>

<link name="back_wheel_roller3">
  <visual>
    <geometry>
      <cylinder length="0.15" radius="0.05"/>
    </geometry>
    <material name="white"/>
  </visual>
  <collision>
    <geometry>
      <cylinder length="0.15" radius="0.05"/>
    </geometry>
  </collision>
  <inertial>
    <mass value="0.1"/>
    <inertia ixx="0.0001" iyy="0.0001" izz="0.0001"/>
  </inertial>
</link>
<joint name="back_wheel_roller3_joint" type="fixed">
  <parent link="back_wheel"/>
  <child link="back_wheel_roller3"/>
  <origin xyz="0.1 0.1732 0" rpy="1.5707 0 1.0472"/>
</joint>

<link name="back_wheel_roller4">
  <visual>
    <geometry>
      <cylinder length="0.15" radius="0.05"/>
    </geometry>
    <material name="white"/>
  </visual>
  <collision>
    <geometry>
      <cylinder length="0.15" radius="0.05"/>
    </geometry>
  </collision>
  <inertial>
    <mass value="0.1"/>
    <inertia ixx="0.0001" iyy="0.0001" izz="0.0001"/>
  </inertial>
</link>
<joint name="back_wheel_roller4_joint" type="fixed">
  <parent link="back_wheel"/>
  <child link="back_wheel_roller4"/>
  <origin xyz="-0.1 -0.1732 0" rpy="1.5707 0 1.0472"/>
</joint>

<link name="back_wheel_roller5">
  <visual>
    <geometry>
      <cylinder length="0.15" radius="0.05"/>
    </geometry>
    <material name="white"/>
  </visual>
  <collision>
    <geometry>
      <cylinder length="0.15" radius="0.05"/>
    </geometry>
  </collision>
  <inertial>
    <mass value="0.1"/>
    <inertia ixx="0.0001" iyy="0.0001" izz="0.0001"/>
  </inertial>
</link>
<joint name="back_wheel_roller5_joint" type="fixed">
  <parent link="back_wheel"/>
  <child link="back_wheel_roller5"/>
  <origin xyz="0.1 -0.1732 0" rpy="1.5707 0 2.0944"/>
</joint>

<link name="back_wheel_roller6">
  <visual>
    <geometry>
      <cylinder length="0.15" radius="0.05"/>
    </geometry>
    <material name="white"/>
  </visual>
  <collision>
    <geometry>
      <cylinder length="0.15" radius="0.05"/>
    </geometry>
  </collision>
  <inertial>
    <mass value="0.1"/>
    <inertia ixx="0.0001" iyy="0.0001" izz="0.0001"/>
  </inertial>
</link>
<joint name="back_wheel_roller6_joint" type="fixed">
  <parent link="back_wheel"/>
  <child link="back_wheel_roller6"/>
  <origin xyz="-0.1 0.1732 0" rpy="1.5707 0 2.0944"/>
</joint>


  <link name="main_color">
    <visual>
      <geometry>
        <box size="0.75 0.375 0.01"/>
      </geometry>
    </visual>
    <collision>
      <geometry>
        <box size="0.75 0.375 0.01"/>
      </geometry>
    </collision>
    <inertial>
      <mass value="0.1"/>
      <inertia ixx="0.095" ixy="0.0" ixz="0.0" iyy="0.381" iyz="0.0" izz="0.476"/>
    </inertial>
  </link>
    <joint name="main_color_joint" type="fixed">
      <parent link="chassis"/>
      <child link="main_color"/>
      <origin rpy="0 0 0" xyz="0 0.1875 0.385"/>
    </joint>

    <link name="secondary_color1">
    <visual>
      <geometry>
        <box size="0.375 0.375 0.01"/>
      </geometry>
    </visual>
    <collision>
      <geometry>
        <box size="0.375 0.375 0.01"/>
      </geometry>
    </collision>
    <inertial>
      <mass value="0.1"/>
      <inertia ixx="0.095" ixy="0.0" ixz="0.0" iyy="0.381" iyz="0.0" izz="0.476"/>
    </inertial>
  </link>
    <joint name="secondary_color_joint1" type="fixed">
      <parent link="chassis"/>
      <child link="secondary_color1"/>
      <origin rpy="0 0 0" xyz="0.1875 -0.1875 0.385"/>
    </joint>

    <link name="secondary_color2">
    <visual>
      <geometry>
        <box size="0.375 0.375 0.01"/>
      </geometry>
    </visual>
    <collision>
      <geometry>
        <box size="0.375 0.375 0.01"/>
      </geometry>
    </collision>
    <inertial>
      <mass value="0.1"/>
      <inertia ixx="0.095" ixy="0.0" ixz="0.0" iyy="0.381" iyz="0.0" izz="0.476"/>
    </inertial>
  </link>
    <joint name="secondary_color_joint2" type="fixed">
      <parent link="chassis"/>
      <child link="secondary_color2"/>
      <origin rpy="0 0 0" xyz="-0.1875 -0.1875 0.385"/>
    </joint>


</robot>